Workbook

Sheet ЛИК_дляСкорингаДП
A1: ОГРН | B1: ИНН | C1: Краткое наименование | D1: Полное наименование | E1: ОКПО | F1: ОКАТО | G1: ОКФС | H1: ОКОПФ | I1: КПП | J1: Регистрация | K1: Ликвидация | L1: ОКВЭД | M1: ОКВЭД наименование | N1: Доп. ОКВЭД | O1: Руководитель | P1: ИНН руководителя | Q1: Должность | R1: Адрес | S1: Телефоны | T1: Web-сайты | U1: Email | V1: Уст. капитал | W1: Выручка (2025) | X1: Осн. средства (2025) | Y1: Запасы (2025) | Z1: Деб. задолженность (2025) | AA1: Кред. задолженность (2025) | AB1: Чистая прибыль (2025) | AC1: Прибыль от продаж (2025) | AD1: прибыль до налогообложения (2025) | AE1: РМСП | AF1: кол-во сотрудников | AG1: Налоговый режим
A2: 1027700092661 | B2: 7712040126 | C2: ПАО "АЭРОФЛОТ" | D2: ПУБЛИЧНОЕ АКЦИОНЕРНОЕ ОБЩЕСТВО "АЭРОФЛОТ-РОССИЙСКИЕ АВИАЛИНИИ" | E2: 29063984 | F2: 45286552000 | G2: 41 | H2: 12247 | I2: 770401001 | J2: 1994-06-21 | L2: 51.10.1 | M2: Перевозка воздушным пассажирским транспортом, подчиняющимся расписанию | N2: 49.39.39,51.21.1,52.23.19,52.29,61.90.9,68.20.29,85.42.9,86.21,18.12,33.16,41.20,46.14,51.10.1,51.21.3,52.29,55.10,56.10.1,58.19,62.01,62.02,62.09,64.99,68.32.2,70.22,73.20,79.11,85.22,85.42.9,86.21 | O2: АЛЕКСАНДРОВСКИЙ СЕРГЕЙ ВЛАДИМИРОВИЧ | P2: 770177090572 | Q2: ГЕНЕРАЛЬНЫЙ ДИРЕКТОР | R2: 119019, Г.МОСКВА, УЛ. АРБАТ, Д. 1 | S2: +74956641319,+74955781384,+74995006762,+74995007624,+74995007258,+79091647126,+74957538163,+74995006765,+74957551500,+78432009585,+74212783456,+74952584082,+74957529016,+74242788555,+74152300722,+79091994636,+74955443312,+74995006868,+74952235555,+79039310032,+74956640001,+74957538188,+71278345684,+72300722842,+72901684995,+70068688415,+78288432009,+75858903931,+78584952584,+70032849575,+70828903931,+73849525840,+73884320095,+72427885558,+78495753816,+74957538004,+74957538063,+74952580684,+74995006867,+74955443329,+74992463049,+74995006700,+74991556648,+74995006800,+74957529031,+74992235555,+74956641201,+74995006481,+73833196860,+74995507624 | T2: emitent@aeroflot.ru,,www.aeroflot.ru | U2: info@aeroflot.ru,ostepanov@aeroflot.ru,trade@aeroflot.ru,obodrova@aeroflot.ru,vgnikolaev@aeroflot.ru,saveliev@aeroflot.ru,info-afl@aeroflot.ru,imoskovaya@aeroflot.ru,yusannikov@aeroflot.ru,vminaev@aeroflot.ru,aableeva@aeroflot.ru,dbalakina@aeroflot.ru,ookorolev@aeroflot.ru,grkkp@aeroflot.ru,vakuzmin@aeroflot.ru,ankuznetsov3@aeroflot.ru,uussales@aeroflot.ru,arbat1@aeroflot.ru,inikolaenko@aeroflot.ru,rtwapsu@aeroflot.ru,krrapsu@aeroflot.ru,oshulga@aeroflot.ru,rtwapsuч@aeroflot.ru,ledtosu@aeroflot.ru,skorolev@aeroflot.ru,obadrova@aeroflot.ru,dsotnichenko@aeroflot.ru,yumelnik@aeroflot.ru,akhaliulin@aeroflot.ru,eakurochkin@aeroflot.ru,vvankevich@aeroflot.ru,asftosu@aeroflot.ru,vogtosu@aeroflot.ru,atarakanova@aeroflot.ru,yakhalaev@aeroflot.ru,kuftosu@aeroflot.net,khvsu@aeroflot.ru,rkashaev@aeroflot.ru,uusapsu@aeroflot.ru,aeroflot@atnet.ru,nsmolyannikova@aeroflot.ru,omssales@aeroflot.ru,peetosu@aeroflot.ru,dmalinov@aeroflot.ru,ovbtosu@aeroflot.ru,ikamaletdinov@aeroflot.ru,sspakhova@aeroflot.ru,omsapsu@aeroflot.ru,nplyasunova@aeroflot.ru,tjmtosu@aeroflot.ru | V2: 3975771215 | W2: 760401133000 | X2: 457204966000 | Y2: 78738975000 | Z2: 135207149000 | AA2: 240967255000 | AB2: 123037451000 | AC2: -14589929000 | AD2: 160180997000 | AG2: ОСН
A3: 1067746341024 | B3: 7708591995 | C3: ПАО "ТРАНСКОНТЕЙНЕР" | D3: ПУБЛИЧНОЕ АКЦИОНЕРНОЕ ОБЩЕСТВО "ТРАНСКОНТЕЙНЕР" | E3: 94421386 | F3: 46483000000 | G3: 41 | H3: 12247 | I3: 504701001 | J3: 2006-03-04 | L3: 52.29 | M3: Деятельность вспомогательная прочая, связанная с перевозками | N3: 35.30.14,46.90,49.41.1,52.24.2,68.20.29,16.23,29.20,30.2,33.11,33.12,33.17,35.30,41.2,43.11,43.12,45.11,45.19,45.20,46.69,46.77,46.90,47.99,49.20,49.41,52.10,52.2,52.21,52.24,52.29,68.1,68.2,69.20,69.20.2,70.22,73.20.1,77.12,77.3,77.39,82.20 | O3: МАРКОВ ВИКТОР НИКОЛАЕВИЧ КОНЦЕРЕВ МИХАИЛ РУДОЛЬФОВИЧ | P3: 772900803304 781400896256 | Q3: ДИРЕКТОР ПРЕЗИДЕНТ | R3: 141402, МОСКОВСКАЯ ОБЛАСТЬ, Г.О. ХИМКИ, Г ХИМКИ, УЛ ЛЕНИНГРАДСКАЯ, ВЛД. 39, СТР. 6, ОФИС 3 (ЭТАЖ 6) | S3: +74922486079,+79035505976,+74957881717,+74952627578,+74992626135,+74956379178,+74952661186,+74956096168,+74992625171,+74992628506,+74952628506,+74992627578,+74992627425,+79144837765,+73466467506,+79102522856,+73022220029,+73912480036,+74992627700,+73912480031,+73022225925,+78124589115,+74852230257,+74852205072,+73912480045,+78312484253,+73022225469,+78632594676,+73832222100,+74991548202,+74212385472,+74852230120,+78124589118,+78124586800,+74732653508,+73433801245,+74212384752,+78452390054,+78452390048,+73952645948,+78632590898,+78632699228,+78463032468,+73952645950,+73832294757,+74732558323,+73022325211,+78124586804,+74732652874,+78124586815 | T3: www.e-disclosure.ru/portal/company.aspx?id=11194,,www.trcont.ru | U3: trcont@trcont.ru,zykinaes@trcont.ru,davidovatn@trcont.ru,zszd@trcont.ru,popyvanovaag@trcont.ru,secretar_dvgd@trcont.ru,ikonnikovaev@trcont.ru,medvedevamp@trcont.ru,kotygavg@trcont.ru,beliakovail@trcont.ru,burkutovaks@trcont.ru,mishinayu@trcont.ru,belyakovail@trcont.ru,obukhovichtv@trcont.ru,shorenkovaa@trcont.ru,demidovaon@trcont.ru,volozhaninmiu@trcont.ru,uskovanm@trcont.ru,konoplevdv@trcont.ru,smirnovagaa@trcont.ru,natalyp@pvrr.ru,svzd@trcont.ru,dvzd@tcont.ru,gzd@trcont.ru,uvzd@trkont.ru,vszd@trcont.ru,kiselevanv@trcont.ru,tripeletcmv@trcont.ru,kruglovaa@trcont.ru,bochkarevpi@trcont.ru,izvekovaen@trcont.ru,kozlovmib@trcont.ru,elenskiyam@trcont.ru,stankevskiysa@trcont.ru,didykmp@trcont.ru,liapinskoviv@trcont.ru,zlydnevani@trcont.ru,tokarevvn@trcont.ru,iasinskiyss@trcont.ru,omelchenkoan@trcont.ru,andreevio@trcont.ru,vasinav@trcont.ru,kuleshovea@trcont.ru,boldorzhievaviu@trcont.ru,golenevai@trcont.ru,erbiaginamv@trcont.ru,kulkovrs@trcont.ru,belosheykinaov@trcont.ru,korneeviuv@trcont.ru,titkovsn@trcont.ru | V3: 13894778000 | W3: 159888098000 | X3: 122577344000 | Y3: 1550744000 | Z3: 24634580000 | AA3: 13611376000 | AB3: -9221825000 | AC3: 9769387000 | AD3: -12214316000 | AG3: ОСН
A4: 1097746772738 | B4: 7708709686 | C4: АО "ФПК" | D4: АКЦИОНЕРНОЕ ОБЩЕСТВО "ФЕДЕРАЛЬНАЯ ПАССАЖИРСКАЯ КОМПАНИЯ" | E4: 94154560 | F4: 45286565000 | G4: 41 | H4: 12267 | I4: 770801001 | J4: 2009-12-03 | L4: 49.10.1 | M4: Перевозка пассажиров железнодорожным транспортом в междугородном сообщении | N4: 26.5,35.30.14,36.00,45.20,47.11,47.19,47.73,47.74,47.75,47.9,49.10,49.20,49.20,49.3,49.4,52.10,52.21,52.24,52.29,55.90,56.10,56.10.1,56.10.3,56.29,58,59.1,63.11.1,68.20,73.11,74.90.31,77.2,77.3,77.39,79.11,85.30,85.42,85.42.9,90.04,91.01,91.02,91.03,93.11,93.19,96.04 | O4: ПЯСТОЛОВ ВЛАДИМИР ГЕННАДЬЕВИЧ | P4: 740404334042 | Q4: ГЕНЕРАЛЬНЫЙ ДИРЕКТОР | R4: 107078, Г.МОСКВА, УЛ МАШИ ПОРЫВАЕВОЙ, Д. 34 | S4: +78512323240,+78512324212,+74992608474,+74992623349,+78312482346,+73952450950,+78463391044,+78124574173,+73472291767,+74992662278,+74212310765,+74992661276,+74992604398,+78312488352,+73433582758,+74992601356,+78452521214,+78463390441,+78463038654,+73433582463,+74992625192,+78463034679,+74992606634,+78312486414,+78632382844,+78124367178,+73832293306,+78312488911,+74955393886,+78124045084,+74992608602,+78632590648,+73433583957,+78463038468,+74959881000,+73832294124,+73952637405,+73952643266,+78463034244,+78463037390,+71242310765,+78312486737,+78452983061,+78632596918,+78312486491,+78312486242,+78312486069,+74212384692,+78452983065,+73472291004 | T4: disclosure.skrin.ru/disclosure/7708709686,,fpc.rzd.ru/static/public/ru?structure_id=14,fpc54.ru | U4: delo@fpc.ru,vasilkovsv@fpc.ru,kravchukyv-kuyb@fpc.ru,chernyavinadu-priv@fpc.ru,lapshinaey-gork@fpc.ru,debunovav@fpc.ru,kaplinamv@fpc.ru,popovaoa-szap@fpc.ru,korolevasn-szap@fpc.ru,klimovaia-vsib@fpc.ru,korotkovang-msk@fpc.ru,rcoz_ovchinnikovve@grw.ru,artemevaya-ural@fpc.ru,sadykovnn@center.rzd.ru,miniakhmetovdh-kuyb@fpc.ru,shprungve@center.rzd.ru,rkz_vlasovvo@msk.rzd.ru,khalatovasa-daln@fpc.ru,chernovvv-ural@fpc.ru,kochevav@fpc.ru,behuv-skav@fpc.ru,voevodinayo-kuyb@fpc.ru,yatcichenkoia-kuyb@fpc.ru,pashkovau@fpc.ru,lynovadv@fpc.ru,ckz_mashinskaya@orw.ru,bochkarevaav-gork@fpc.ru,Аlekseevatv-zsib@fpc.ru,rcoz_skopinamv@grw.ru,koreginaas-szap@fpc.ru,chernoskutovann@fpc.ru,rcoz_artemovka@grw.ru,bariomi@center.rzd.ru,alekseevatv-zsib@fpc.ru,barskayaeg-daln@fpc.ru,sgpetrova@svrw.ru,skzd-iruban@skzd.rzd.ru,trubilinalv-vsib@fpc.ru,korolevaav-kuyb@fpc.ru,ryabykhai-kuyb@fpc.ru,tagilcevaeb@wsr.ru,ivanovanv-priv@fpc.org.rzd,yashinala@fpc.ru,zuevanv-priv@fpc.ru,rсоz_makarovpv@esrr.ru,kuznecovsa-kuyb@fpc.ru,rcoz_makarovpv@esrr.ru,slynkoas-kuyb@fpc.ru,rkz-terentevan@kbsh.rzd.ru,rckz_medvedevav@dvgd.ru | V4: 263588838994 | W4: 427758435000 | X4: 437693243000 | Y4: 11603320000 | Z4: 24030311000 | AA4: 60554694000 | AB4: 19596889000 | AC4: 45942576000 | AD4: 27506070000 | AG4: ОСН
A5: 1067746082546 | B5: 7708587205 | C5: АО "РЖДСТРОЙ" | D5: АКЦИОНЕРНОЕ ОБЩЕСТВО "РЖДСТРОЙ" | E5: 93287520 | F5: 45286555000 | G5: 41 | H5: 12267 | I5: 770901001 | J5: 2006-01-19 | L5: 43.12 | M5: Подготовка строительной площадки | N5: 23.32,23.51,23.61,25.11,37.00,41.10,41.2,41.20,42.11,42.12,42.13,42.91,42.99,43.11,43.12.3,43.2,43.21,43.22,43.29,43.3,43.39,43.91,43.99,43.99.1,46.73,47.52.7,49.20,68.20,71.12.1,71.12.2,71.12.45,77.32 | O5: МАЛЬЦЕВ ЮРИЙ СЕРГЕЕВИЧ | P5: 150405977663 | Q5: ГЕНЕРАЛЬНЫЙ ДИРЕКТОР | R5: 105005, Г.МОСКВА, ПЕР. ЕЛИЗАВЕТИНСКИЙ, Д. 12, СТР. 1 | S5: +78512322996,+78512323866,+74992668800,+74992613337,+74997530634,+74952680051,+79035380745,+74012601160,+79108813414,+73952644331,+74992603432,+79281279352,+74991873614,+78452412083,+79241007607,+78452744077,+79093913913,+74212911361,+79106662575,+73912482439,+78124364734,+73022225771,+78632590467,+74992662869,+78632594104,+78632638256,+79807400829,+74212911374,+73952643377,+79243099638,+74991873616,+74212911365,+74212382712,+74992604398,+78312483552,+74955005018,+74992662726,+74732655443,+74992662681,+74952668800,+74955434000,+78632035784,+74212911366,+78421911366,+74232249417,+74630349808,+79171092027,+74012587230,+74955005019,+78632638254 | T5: www.rzdstroy.ru,,www.rzdstroy.ru | U5: info@rzdstroy.ru,boroninav@rzdstroy.ru,chuvankinab@rzdstroy.ru,sevostyanovrs@rzdstroy.ru,tokarevaaa@rzdstroy.ru,avetisyanis@rzdstroy.ru,parfulindg@rzdstroy.ru,zheleznovaei@rzdstroy.ru,myagkovaev@rzdstroy.ru,nikolaevds@rzdstroy.ru,shepchugovaap@rzdstroy.ru,moskovkinaes@rzdstroy.ru,lugovskayatv@rzdstroy.ru,pomeshikovals@rzdstroy.ru,shirokovav@rzdstroy.ru,pilipenkoem@rzdstroy.ru,ilinata@rzdstroy.ru,bizyaevaov@rzdstroy.ru,ratkinamn@rzdstroy.ru,kopylovaim@rzdstroy.ru,goncharovaoi@rzdstroy.ru,leonovaev@rzdstroy.ru,milovds@rzdstroy.ru,kosheevaka@rzdstroy.ru,uspenskayant@rzdstroy.ru,filkinaeo@rzdstroy.ru,korolevaey@rzdstroy.ru,odintsovas@rzdstroy.ru,ocheredkooe@rzdstroy.ru,stadnichenkoei@rzdstroy.ru,dyakonovaas@rzdstroy.ru,lesnovng@rzdstroy.ru,vasukovsn@rzdstroy.ru,hizhnyakovayv@rzdstroy.ru,kravetson@rzdstroy.ru,andreikouv@rzdstroy.ru,bogdanovana@rzdstroy.ru,somikey@rzdstroy.ru,shlemchenkoep@rzdstroy.ru,maximovda@rzdstroy.ru,solovevatv@rzdstroy.ru,sadykovnn@center.rzd.ru,garikhinoe@rzdstroy.ru,karelinsv@rzdstroy.ru,kozlovev@rzdstroy.ru,elfimovaev@rzdstroy.ru,andreykouv@rzdstroy.ru,bobylevaap@rzdstroy.ru,udalcovama@rzdstroy.ru,slonkinsg@rzdstroy.ru | V5: 14176805000 | W5: 117762144000 | X5: 5389211000 | Y5: 8385986000 | Z5: 41310670000 | AA5: 73734110000 | AB5: -17820406000 | AC5: -3882051000 | AD5: -11097891000 | AG5: ОСН
A6: 1117746460358 | B6: 7704784450 | C6: АО "ИНТЕР РАО-ЭЛЕКТРОГЕНЕРАЦИЯ" | D6: АКЦИОНЕРНОЕ ОБЩЕСТВО "ИНТЕР РАО-ЭЛЕКТРОГЕНЕРАЦИЯ" | E6: 92516444 | F6: 45286590000 | G6: 16 | H6: 12267 | I6: 770401001 | J6: 2011-06-15 | L6: 35.11.1 | M6: Производство электроэнергии тепловыми электростанциями, в том числе деятельность по обеспечению работоспособности электростанций | N6: 25.62,33.12,33.14,35.11.2,35.14,35.23,35.30.11,35.30.14,35.30.4,36.00.1,36.00.2,37.00,46.90,49.42,49.50.21,52.10.21,52.10.9,52.21.11,61.10.1,68.20.1,68.20.29,69.20.2,71.20.4,77.39.11,77.39.23,77.39.29,82.99,93.11,96.09.9,03.21.4,03.22.5,20.11,23.61,33.13,33.14,33.14,33.20,35.11,35.11.1,35.11.1,35.11.2,35.11.2,35.12,35.12,35.13,35.14,35.14,35.22,35.30.1,35.30.11,35.30.14,35.30.2,35.30.3,35.30.4,35.30.5,36.00.1,36.00.2,37.00,37.00,41.2,41.20,42.21,42.22.1,42.22.3,43.21,46.71,46.90,49.20,49.3,49.4,49.41.1,49.41.2,49.50.21,49.50.22,52.10,52.10.21,52.10.23,52.21.1,52.21.2,52.24,56.29,61.10.1,68.10,68.20,68.20.1,68.20.2,68.32,70.10.1,70.10.2,70.22,71.12.1,71.12.6,71.12.62,71.20.1,72.19,73.20,77.39,85.23,85.42,86.21,86.23,86.90.4,91.01,93.11,96.09 | O6: ОБЩЕСТВО С ОГРАНИЧЕННОЙ ОТВЕТСТВЕННОСТЬЮ "ИНТЕР РАО - УПРАВЛЕНИЕ ЭЛЕКТРОГЕНЕРАЦИЕЙ" | P6: 7704775342 | Q6: — | R6: 119435, Г.МОСКВА, УЛ. БОЛЬШАЯ ПИРОГОВСКАЯ, Д.27, СТР.1 | S6: +73014595437,+74945372855,+74945372863,+74956647680,+73426593950,+74945372062,+73426593234,+73426595002,+74945372246,+73014595367,+73426593000,+73014595327,+73014595572,+74945372860,+74012690449,+74012690448,+74945372708,+74945372648,+74945372834,+73426593306,+79632929980,+74012690453,+73014595326,+79632973711,+74016140610,+73014595651,+74945372818,+74945372822,+74945372253,+73014595344,+74012690263,+73014595491,+79044975203,+74014336160,+73536351207,+73513492396,+74012690423,+73516672531,+73536351247,+73426593260,+73435722308,+73014595349,+73494246713,+79243936695,+73494246723,+73494246671,+79245501153,+79245501152,+74012690367,+79245501154 | T6: www.e-disclosure.ru/portal/company.aspx?id=29767,,www.interrao.ru/activity/generation/disclosure,pechgres.ru | U6: titova_eo@interrao.ru,surzhikova_ys@interrao.ru,alekseeva_aa@interrao.ru,tyurnikova_mb@interrao.ru,nazarova_va@interrao.ru,merkusheva_ta@interrao.ru,dmitrieva_ap@interrao.ru,golubeva_ly@interrao.ru,loskutnikov_am@interrao.ru,lebusova_on@interrao.ru,baldina_en@interrao.ru,prikhodko_ey@interrao.ru,nechaeva_tv@interrao.ru,likhacheva_ev@interrao.ru,suranov_av@interrao.ru,bulatova_avl@interrao.ru,moroz_tr@interrao.ru,ivanova_iv@interrao.ru,gavrilyuk_db@interrao.ru,shubin_rv@interrao.ru,brusnikina_in@interrao.ru,smotrichenko_ee@interrao.ru,shushpanova_ne@interrao.ru,svarin_es@interrao.ru,kabakova_iv@interrao.ru,gorokhova_aa@interrao.ru,kanashina_iv@interrao.ru,korenkova_ts@interrao.ru,frolov_svl@interrao.ru,efimova_tp@interrao.ru,dubova_ma@interrao.ru,kravchenko_ko@interrao.ru,pakush_av@interrao.ru,mokhova_nn@interrao.ru,karyakina_ym@interrao.ru,gosuslugi_eg@interrao.ru,nikiforova_yv@interrao.ru,naumkina_ms@interrao.ru,kutlaeva_er@interrao.ru,frolova_ty@interrao.ru,abramova_nan@interrao.ru,nosova_ns@interrao.ru,balbatunova_ey@interrao.ru,sd@vtgres.ogk1.ru,batalova_ea@interrao.ru,wwwinter-rao@mail.ru,lytkina_ya@interrao.ru,kazunina_dv@interrao.ru,chistyakova_ov@interrao.ru,shishkova_iv@interrao.ru | V6: 172491169361 | W6: 293934892000 | X6: 240926685000 | Y6: 14660876000 | Z6: 34992223000 | AA6: 19752065000 | AB6: 67561454000 | AC6: 54744900000 | AD6: 90248644000 | AG6: ОСН
A7: 5087746119951 | B7: 7721632827 | C7: АО "КОНЦЕРН РОСЭНЕРГОАТОМ" | D7: АКЦИОНЕРНОЕ ОБЩЕСТВО "РОССИЙСКИЙ КОНЦЕРН ПО ПРОИЗВОДСТВУ ЭЛЕКТРИЧЕСКОЙ И ТЕПЛОВОЙ ЭНЕРГИИ НА АТОМНЫХ СТАНЦИЯХ" | E7: 8844275 | F7: 45290554000 | G7: 61 | H7: 12267 | I7: 772101001 | J7: 2008-09-17 | L7: 35.11.3 | M7: Производство электроэнергии атомными электростанциями, в том числе деятельность по обеспечению работоспособности электростанций | N7: 35.11.3,35.12,35.12,35.13,35.30.12,35.30.2,35.30.3,35.30.5,36.00.1,37.00,38.1,38.2,42.22.3,42.99,43.21,51.10,55.10,55.90,61.10,63.11,70.22,71.11.1,71.12,71.12.1,71.12.45,71.20,72.19,84.24,85.30,85.42,86.90.4 | O7: ШУТИКОВ АЛЕКСАНДР ВИКТОРОВИЧ | P7: 643909165462 | Q7: ГЕНЕРАЛЬНЫЙ ДИРЕКТОР | R7: 109507, Г.МОСКВА, УЛ. ФЕРГАНСКАЯ, Д.25 | S7: +74953770213,+78136922518,+74956474354,+74956605001,+74956609070,+74956434754,+74957106363,+74999494740,+74957830143,+73437736940,+79859703601,+74956474370,+74957106546,+74815370611,+78639219872,+78153243798,+78153244787,+78153243627,+78136954317,+78136954328,+78136954329,+78453497141,+74815330440,+78136954315,+74825569048,+74273825759,+74736473472,+78453497294,+78453497180,+74713156371,+78136954316,+78136954313,+78153243957,+78136954311,+74736473671,+78639297022,+78453497823,+74713157277,+78639297757,+78453497810,+74713153783,+78153242140,+74736473302,+73437738105,+74825569159,+78453499818,+78639298724,+74815330441,+74825569251,+78639223739 | T7: sanatorij-balaes.ru,www.rosenergoatom.ru/stations_projects/sayt-novovoronezhskoy-aes/,www.salma-ski.ru,www.e-disclosure.ru/portal/company.aspx?id=18936,,www.rosenergoatom.ru | U7: kev@belnpp-auto.ru,post@belnpp.ru,sokolov@balaes.ru,profk@kolatom.murmansk.ru,panitskiyae@kolnpp.rosenergoatom.ru,salma-ski@yandex.ru,surkova@balaes.ru,beketova-sa@vdnpp.rosenergoatom.ru,kolanpp@kolatom.murmansk.ru,spf@belnpp.ru,reception@knpp.local,nvnpp1@nvnpp1.rosenergoatom.ru,kopan.laes@yandex.ru,voropaevaap@saes.ru,nechatvys@yandex.ru,info@rosenergoatom.ru,info@atomkomplekt.org,abramova-eka@rosenergoatom.ru,rakov-vv@rosenergoatom.ru,cz19@belnpp.ru,anvlprikhodko@rosatom.ru,gajdukova-ii@btaes.ru,savina-ys@rosenergoatom.ru,baibenkova-mn@rosenergoatom.ru,medvedeva22@rosenergoatom.ru,cz3@belnpp.ru,tabunshchikyv@odic.rosenergoatom.ru,cz-sov@ln.rosenergoatom.ru,turutina@balaes.ru,bekmambetov@saes.ru,lapkin_ou@kunpp.ru,anisimovav@kolnpp.rosenergoatom.ru,melnikova_ti@kunpp.ru,turganova@balaes.ru,rybakova-iv@bilnpp.ru,cz9@belnpp.ru,npp@balaes.ru,matveev_en@kunpp.ru,cz-reu@ln.rosenergoatom.ru,safronovav@nvnpp1.rosenergoatom.ru,frkp_zakupki@rosenergoatom.ru,borodina@kunpp.ru,evgrafova_as@knpp.ru,soboleva_tn@kunpp.ru,od-cpv@ln.rosenergoatom.ru,avdeeva@knpp.ru,bogdanov-ia@bilnpp.ru,shakurova-og@knpp.ru,cz-lav@ln.rosenergoatom.ru,sambulovrv@odic.rosenergoatom.ru | V7: 830313906474 | W7: 689530314000 | X7: 1990136600000 | Y7: 82659832000 | Z7: 96167823000 | AA7: 108998064000 | AB7: 133373947000 | AC7: 242569601000 | AD7: 201913926000 | AG7: ОСН
A8: 5087746570830 | B8: 7715729877 | C8: АО "ЖЕЛДОРРЕММАШ" | D8: АКЦИОНЕРНОЕ ОБЩЕСТВО "ЖЕЛДОРРЕММАШ" | E8: 94138851 | F8: 45280569000 | G8: 41 | H8: 12267 | I8: 771501001 | J8: 2008-12-09 | L8: 30.20.9 | M8: Предоставление услуг по восстановлению и оснащению (завершению) железнодорожных локомотивов, трамвайных моторных вагонов и прочего подвижного состава | N8: 16.24,16.29.11,18.12,22.19.7,23.61,25.50.1,25.61,25.62,25.73,28.15.2,30.20.1,30.20.4,33.12,33.14,33.17,33.20,35.12,35.13,35.22,35.30.14,35.30.2,35.30.3,35.30.4,36.00.2,38.32.5,41.20,43.11,43.12.1,43.12.3,43.29,46.69.1,46.69.2,46.77,46.90,47.9,49.10,49.20,49.3,49.31,49.4,49.41.2,52.21.1,55.10,55.90,56.10,56.10.1,56.10.3,56.29,61.10.1,62.01,62.02,62.09,63.11.1,68.20.1,68.20.2,68.32.1,71.1,71.11,71.11.1,71.12.12,71.12.45,71.12.5,71.12.6,71.20,72.1,72.19,73.20.1,74.20,74.30,82.92,82.99,85.42,85.42.9,86.21,91.01 | O8: МАВРИН АЛЕКСАНДР НИКОЛАЕВИЧ | P8: 616206292791 | Q8: ГЕНЕРАЛЬНЫЙ ДИРЕКТОР | R8: 127018, Г.МОСКВА, УЛ. ОКТЯБРЬСКАЯ, Д.5, СТР.8 | S8: +79092859495,+74992621737,+74992620106,+74234263081,+74996382298,+78006000669,+74234232385,+74234232331,+78512210112,+73012444340,+73517914731,+70006698851,+78184992620,+71068499262,+72210112830,+71737849963,+78229888006,+72342323318,+71842342630,+71244434084,+78351791473,+74992627117,+74732008213,+78632409130,+74234260070,+74852406749,+74234232435,+74234252525,+73012446626,+73012371756,+74234360594,+78632406134,+73517914333,+78512210152,+73517914165,+74732653831,+74732531560,+78622528320,+73433312627,+78632402044,+78512301812,+74852773000,+73833376448,+73833377142,+78512301465,+74852406761,+73532566183,+73433119702,+73833375486,+74234367507 | T8: e-disclosure.azipi.ru/organization/800330/,,www.olrz.ru,www.ao-zdrm.ru | U8: urlz@mail.ussuriisk.ru,matveevala@locotech.ru,lapinaea@ulrz.ru,energi-rerz@ao-zdrm.ru,omto@r56.fssprus.ru,ulrz@ml.ussuriisk.ru,lapinaea@locotech.ru,ulrz@uirz.ru,уссуржелдоррем@mail.ru,ulrz@ulrz.ru,urlz@ml.ussuriisk.ru,u.kalmikova@cherz.ru,info@yarz.ru,olgakalashnikova0371@gmail.com,energi-rerz@ао-zdm.ru,atrz@locotech.ru,mail@ing.center.ru,erz@erz.ru,atrz@astranet.ru,olrz@olrz.ru,nerz@nerz.ru,rerz@lokotech.ru,vrntrz@ttk-uv.ru,oge-ulrz@yandex.ru,vtrz@locotech.ru,uss_ds101@mail.ru,savvateevaov-oge@uirz.ru,pavel@lvrz.ru,00000@mail.ru,bely@loco.ru,detsadik106@mail.ru,ulrz@ao-zdrm.ru,savvateevaov-oge@ulrz.ru,ooo_teplo@mail.ru,0@mail.ru,omto@r56.fsshrus.ru,geidorrem@mail.ru,lvrz@lvrz.ru,dboroda73@mail.ru,kirichenkovo-ogmeh@ulrz.ru,birukovael-oopz@ulrz.ru,auction@locotech.ru,1@mail.ru,energy-rerz@ao-zdrm.ru,oozp-ulrz@ao-zdrm.ru,kuzyakinva@locotech.ru,geldorrem@mail.ru,cherz-odc@mail.ru,otv-zdrm@css-rzd.ru,rem@mail.ru | V8: 15162764668 | W8: 89893496000 | X8: 13262416000 | Y8: 17597199000 | Z8: 37509656000 | AA8: 26363392000 | AB8: 4067863000 | AC8: 9445655000 | AD8: 5465281000 | AG8: ОСН
A9: 1057747320278 | B9: 7728551528 | C9: ООО "СПОРТМАСТЕР" | D9: ОБЩЕСТВО С ОГРАНИЧЕННОЙ ОТВЕТСТВЕННОСТЬЮ "СПОРТМАСТЕР" | E9: 77522772 | F9: 45293566000 | G9: 23 | H9: 12300 | I9: 772801001 | J9: 2005-06-27 | L9: 47.71 | M9: Торговля розничная одеждой в специализированных магазинах | N9: 46.49,47.91,53.20.39,95.29,37.00,46.42.11,46.42.12,46.42.13,46.42.14,46.42.2,47.25,47.64,47.71.1,47.71.2,47.71.3,47.71.4,47.71.5,47.71.6,47.71.7,47.71.8,47.72.1,47.72.2,47.74,47.78,47.91.2,52.10,53.20.3,62.01,62.02,68.31.12,73.11,85.42,85.42.9,95.11,95.29 | O9: СТРАХОВ ЛЕОНИД БОРИСОВИЧ | P9: 772728563630 | Q9: ГЕНЕРАЛЬНЫЙ ДИРЕКТОР | R9: 117437, Г.МОСКВА, УЛ. МИКЛУХО-МАКЛАЯ, Д.18, К.2, КОМН. 102 | S9: +74922323940,+73512634142,+74957558143,+74957558194,+74957777771,+73522600625,+74957558190,+74957558184,+74957558197,+74959747522,+74959747890,+74959747934,+74957558179,+73472912151,+73472922151,+73432165154,+73432165151,+73473290843,+78123200002,+78452201864,+73022282244,+73812325174,+73722533106,+78612775522,+79282611111,+73832300844,+78632559555,+79138005302,+73822900715,+79039170663,+79517237800,+74954116923,+74954116922,+73843910644,+73012297691,+74967545747,+78463722532,+79034000675,+74993502071,+78632559454,+73812321574,+78452207720,+78632870140,+78792252680,+74242708620,+73953560003,+73822283367,+73412916916,+73412903838,+73843390358 | T9: www.sportmaster.ru | U9: legal@sportmaster.ru,asergienko@sportmaster.ru,okorotaeva@sportmaster.ru,sportmaster@mail.ru,ovlaskina@sportmaster.ru,nfilippova@sportmaster.ru,tmazurova@sportmaster.ru,skonovalova@sportmaster.ru,director5886@sportmaster.ru,info@grrus.ru,okarelina@sportmaster.ru,rostov@czn-rostov.ru,vaeremeeva@sportmaster.ru,emakanova@sportmaster.ru,megadirector763@sportmaster.ru,adminshop5198@sportmaster.ru,direktor5581@sportmaster.ru,null@null.ru,account852@sportmaster.ru | V9: 261642499 | W9: 165625072000 | X9: 33077804000 | Y9: 44904585000 | Z9: 12075061000 | AA9: 26105333000 | AB9: 4963645000 | AC9: 14067088000 | AD9: 7112593000 | AG9: ОСН
A10: 1027717003467 | B10: 7717133960 | C10: ПАО НК "РУССНЕФТЬ" | D10: ПУБЛИЧНОЕ АКЦИОНЕРНОЕ ОБЩЕСТВО НЕФТЕГАЗОВАЯ КОМПАНИЯ "РУССНЕФТЬ" | E10: 59107064 | F10: 45286560000 | G10: 34 | H10: 12247 | I10: 770501001 | J10: 2002-09-17 | L10: 06.10.1 | M10: Добыча нефти | N10: 06.10,08.12.1,09.10.1,09.10.9,23.51,28.13,33.20,35.11,35.12,35.13,35.22,35.30.14,46.71,46.71.2,46.71.3,49.41,49.41.1,49.50.11,49.50.21,52.10,52.10.22,52.21.2,52.29,64.20,64.99,69.10,69.20,70.10,70.10.1,70.10.2,71.12,71.12.1,71.20,82.11,84.13 | O10: ТОЛОЧЕК ЕВГЕНИЙ ВИКТОРОВИЧ | P10: 637700276860 | Q10: ПРЕЗИДЕНТ | R10: 115054, Г.МОСКВА, УЛ. ПЯТНИЦКАЯ, Д.69 | S10: +79195300000,+74954116309,+74954116325,+74957805891,+78452393555,+78452393427,+74954116312 | T10: russneft.ru | U10: russneft@russneft.ru,srf@russneft.ru,russneft@mail.ru,vasilevaei@russneft.ru | V10: 196076000 | W10: 221621391000 | X10: 104110496000 | Y10: 12185993000 | Z10: 74520682000 | AA10: 124442818000 | AB10: 7752425000 | AC10: 27792742000 | AD10: 1059615000 | AG10: ОСН
A11: 1065009017920 | B11: 5009053687 | C11: ООО "ТАТНЕФТЬ-АЗС-ЗАПАД" | D11: ОБЩЕСТВО С ОГРАНИЧЕННОЙ ОТВЕТСТВЕННОСТЬЮ "ТАТНЕФТЬ-АЗС-ЗАПАД" | E11: 96277539 | F11: 45268569000 | G11: 16 | H11: 12300 | I11: 773101001 | J11: 2006-07-17 | L11: 47.30 | M11: Торговля розничная моторным топливом в специализированных магазинах | N11: 10.71.1,10.85,68.20.21,10.13.4,10.32,10.71,10.72,10.72.4,10.82,10.82.2,10.85,10.89,11.07.2,19.20,42.21,45.2,45.20.5,46.12.1,46.71,46.71.1,46.71.2,46.90,47.11,47.2,47.24,47.25,47.26,47.30,47.30.2,47.73,47.74,47.75,47.78.9,47.91,47.91.1,47.91.2,47.91.29,49.31,49.50.1,52.10.21,52.29,56.10,56.10.21,56.10.22,56.10.24,56.29,56.30,66.19,73.11,74.20,74.30,77.40,82.92,85.30,85.42.9 | O11: НИЖАМЕТДИНОВ ШАМИЛЬ РАШИДОВИЧ | P11: 771800020650 | Q11: ДИРЕКТОР | R11: 121205, Г.МОСКВА, ВН.ТЕР.Г. МУНИЦИПАЛЬНЫЙ ОКРУГ МОЖАЙСКИЙ, ТЕР ИННОВАЦИОННОГО ЦЕНТРА СКОЛКОВО, Б-Р БОЛЬШОЙ, Д. 62 | S11: +79857731191,+74952801347,+74852726044,+79150274207,+74922421317,+78125503510,+74952801124,+78182462914,+74922420546,+78125500180,+74922421096,+74952211603,+74952211639,+74956441611,+74952211726,+78495280137,+78442984256,+74952211640,+74952211611,+74953339560,+78442984253,+78443589884,+78443586884,+74952271725,+78182622220,+78182622020,+74952211725,+74952801348,+78443580091,+74852726014,+78125503666,+78125500170,+78182652109,+74957899049,+74452211603,+74952211775,+78957661850,+74957775707,+74952211620,+74956455306,+74965553698,+74942211725,+78182602020,+74956441610,+79106625601,+78182621777,+78282622020,+74922726044,+78818622020,+78182621277 | T11: www.azs-tatneft.ru,,www.tatneft.ru | U11: tender@msk.tatneft.ru,tatneft@msk.tatneft.ru,5009053687_772901001@eo.tensor.ru,tatneft34@msk.tatneft.ru,bogomolova@tnvl.ru,bakhtin@azszapad.ru,vyalkin_au@msk.tatneft.ru,artem@azszapad.ru,npvega@mail.ru,нет@mail.ru,tender@msk.tatneft.tu,sekr@tnvl.ru,kubkina_os@msk.tatneft.ru,tat@mail.ru,goricheva@tnvl.ru,mail@azszapad.ru,shikunova_ad@msk.tatneft.ru,tender@vsk.tatneft.ru,1@mail.ru,net@mail.ru,bogomolov_as@msk.tatneft.ru,bahtin@azszapad.ru,tender@msk.tatntft.ru,tnw@yandex.ru,bogomolova@tnvl.ru;,tender@msk.tatneft.ru;,bogomolova@ntvl.ru,tn@mail.ru,ivanova.n@spb.tatneft.ru,info@zenit.ru,fokin_da@msk.tatneft.ru,tatneft@mail.ru,samigullin_kv@msk.tatneft.ru,vrublevskaya_oi@msk.tatneft.ru,famullina_er@msk.tatneft.ru,tender_bi@tatneft.ru,granovskiy_bi@msk.tatneft.ru,polushkina@spb.tatneft.ru,delo@spb.tatneft.ru,info@msk.tataneft.ru,phykj@mail.ru,sekr@tnvt.ru,tender_bi@msk.tatneft.ru,deli@msk.tatneft.ru,pleshkan@tatneft.ru,delo@msk.tatneft.ru,,info@tatneftm.ru,tihonova@spb.tatneft.ru,boqomolova@tnvl.ru,bogomolova@tnv.ru | V11: 3646969080 | W11: 148369814000 | X11: 15480622000 | Y11: 7046460000 | Z11: 13143887000 | AA11: 9103676000 | AB11: 5522836000 | AC11: 5370557000 | AD11: 6870674000 | AG11: ОСН
A12: 1077763638578 | B12: 7704670879 | C12: АО "ИКАО" | D12: АКЦИОНЕРНОЕ ОБЩЕСТВО "ИПОТЕЧНАЯ КОМПАНИЯ АТОМНОЙ ОТРАСЛИ" | E12: 84095282 | F12: 45296559000 | G12: 16 | H12: 12267 | I12: 772501001 | J12: 2007-12-10 | L12: 71.12.2 | M12: Деятельность заказчика-застройщика, генерального подрядчика | N12: 41.2,55.90,64.92.3,68.1,68.2,68.3,70.22,71.11.1 | O12: КИСЕЛЕВ ЮРИЙ МИХАЙЛОВИЧ | P12: 772783125074 | Q12: ВРЕМЕННЫЙ ЕДИНОЛИЧНЫЙ ИСПОЛНИТЕЛЬНЫЙ ОРГАН | R12: 115432, Г.МОСКВА, ВН.ТЕР.Г. МУНИЦИПАЛЬНЫЙ ОКРУГ ДАНИЛОВСКИЙ, ПРОЕЗД ПРОЕКТИРУЕМЫЙ 4062-Й, Д. 6, СТР. 25, ПОМЕЩ. 11 | S12: +74957953799,+74957953967,+79156301777,+79166478963,+74959602086,+74713153488,+74815332977,+78153272184,+74957953767,+74959602085,+74736428506,+78136949393,+74825558022,+78453396140,+79202200600,+78639244771 | U12: ao-ikao@yandex.ru,vyukuzmichev@rosatom.ru,eysavina@rosatom.ru,ao-ikao@rosatom.ru,zaoikao@gmail.com,dmekrylov@rosatom.ru,zaoika@gmail.com,zao.ikao@gmail.com,dedova.2013@list.ru79606939798,krylov.ikao@gmail.com,krylov.ikao@gmai.com | V12: 4427000000 | W12: 445141000 | X12: 286911000 | Y12: 103947000 | Z12: 171202000 | AA12: 37444000 | AB12: 217104000 | AC12: 124168000 | AD12: 293173000 | AF12: 34 | AG12: ОСН
A13: 1117746491500 | B13: 7702764909 | C13: ООО "КАРИ" | D13: ОБЩЕСТВО С ОГРАНИЧЕННОЙ ОТВЕТСТВЕННОСТЬЮ "КАРИ" | E13: 92543151 | F13: 45286565000 | G13: 23 | H13: 12300 | I13: 770801001 | J13: 2011-06-22 | L13: 47.72 | M13: Торговля розничная обувью и изделиями из кожи в специализированных магазинах | N13: 46.42,16.29.13,23.19.9,24.10.2,32.12.1,32.12.2,32.12.3,32.12.4,32.12.5,32.13,38.32.2,38.32.59,46.12.22,46.18.2,46.18.2,46.41,46.41.2,46.42,46.43,46.44,46.45,46.46,46.48.2,46.49,46.72.23,46.76.4,47.19,47.43,47.51,47.54,47.7,47.71,47.72,47.75,47.77.2,47.91,47.91.1,47.91.2,47.91.4,63.99.1,66.19.5,69.10,69.20,70.22,78.10,95.25 | O13: ОБЩЕСТВО С ОГРАНИЧЕННОЙ ОТВЕТСТВЕННОСТЬЮ УПРАВЛЯЮЩАЯ КОМПАНИЯ "КАРИ" | P13: 9729299145 | Q13: — | R13: 107140, Г.МОСКВА, УЛ. РУСАКОВСКАЯ, Д.13 | S13: +79140708917,+74956697002,+79607612362,+74956677002,+74959874807,+74959874806,+79659191692 | T13: www.kari.ru | U13: 10575@kari.com,karu@mail.ru,10387@kari.com | V13: 2000000000 | W13: 98818597000 | X13: 24008361000 | Y13: 58953882000 | Z13: 16406908000 | AA13: 39005199000 | AB13: 2265676000 | AC13: 2784404000 | AD13: 3048046000 | AG13: ОСН
A14: 1037702027670 | B14: 7702354081 | C14: ООО "ЛАР" | D14: ОБЩЕСТВО С ОГРАНИЧЕННОЙ ОТВЕТСТВЕННОСТЬЮ "ЛУКОЙЛ-АЭРО" | E14: 14666926 | F14: 45286555000 | G14: 16 | H14: 12300 | I14: 770901001 | J14: 2003-06-10 | L14: 46.71.2 | M14: Торговля оптовая моторным топливом, включая авиационный бензин | N14: 46.18,70.10,77.39.11,46.71,46.75.2,49.41.1,52.10.21,52.23.1,52.23.12,52.23.19,68.20.2,77.39 | O14: БРАУН ВЛАДИМИР АЛЕКСАНДРОВИЧ | P14: 590201689550 | Q14: ГЕНЕРАЛЬНЫЙ ДИРЕКТОР | R14: 109028, Г.МОСКВА, Б-Р ПОКРОВСКИЙ, Д. 3, СТР. 1 | S14: +79688022610,+74959803113,+74959817087,+74959803114,+78442317101,+78312565226,+78312759650,+74959803938,+70959803113,+73422947711,+70959803114,+73517783274,+74959803100 | U14: aero@lukoil.com,aero@lukoil.ru | V14: 1437325691 | W14: 196514024000 | X14: 2594810000 | Y14: 5171455000 | Z14: 21207903000 | AA14: 20026368000 | AB14: 9927275000 | AC14: 8704071000 | AD14: 12115031000 | AG14: ОСН
A15: 1027700050278 | B15: 7704228075 | C15: АО "РОСАТОМ ЭНЕРГОСБЫТ" | D15: АКЦИОНЕРНОЕ ОБЩЕСТВО "РОСАТОМ ЭНЕРГОСБЫТ" | E15: 57082325 | F15: 45296559000 | G15: 61 | H15: 12267 | I15: 772501001 | J15: 2001-07-13 | L15: 35.14 | M15: Торговля электроэнергией | N15: 47.19,82.99,33.12,35.11,35.13,35.14,45.20.1,47.19,47.91.2,47.91.3,47.91.4,49.39,62.01,62.02,62.02.1,62.02.4,62.03.13,62.09,63.11,63.11.1,66.2,66.22,73.11,74.90.31,77.29,80.10,80.20,80.30,82.99,84.21 | O15: ГОРЧАКОВ АЛЕКСЕЙ НИКОЛАЕВИЧ | P15: 511002181700 | Q15: ГЕНЕРАЛЬНЫЙ ДИРЕКТОР | R15: 115432, Г.МОСКВА, ПР-Д ПРОЕКТИРУЕМЫЙ 4062-Й, Д. 6, СТР. 25 | S15: +74957847701,+78152692359,+78152692421,+74812687500,+74957899921,+74823358716,+74812687555,+74812687533,+78152692323,+78152692633,+78152692318,+74712324072,+74822483019,+74712390301,+74822483015,+74712390303,+74712390312,+74812687586,+74712323995,+74712506196,+74712324502,+74712390321,+78152692627,+74823622897,+74812687575,+74712390310,+74812687550,+74712324102,+74712320312,+74812687571,+74712320301,+74812687526,+74712227018,+74826922135,+74712390315,+74712324302,+74712324010,+74712390317,+74712390324,+74824224301,+74713421466,+74712227021,+74825555498,+74823352873,+74822379367,+74712227014,+74813247160,+74823622144,+74824224300,+74822483016 | T15: atomsbt.ru,www.atomsbt.ru | U15: info@atomsbt.ru,info@murmansk.atomsbt.ru,secretare@tver.atomsbt.ru,secretar@smolensk.atomsbt.ru,atomsbt@mail.ru,pershinans@tver.atomsbt.ru,shleitanovani@tver.atomsbt.ru,korotkikhyg@smolensk.atomsbt.ru,antonyukaa@murmansk.atomsbt.ru,kuzmenkonv@murmansk.atomsbt.ru,arkhipovna@atomsbt.ru,maslennikovaaa@murmansk.atomsbt.ru,usachyovag@smolensk.atomsbt.ru,strelkovaen@kursk.atomsbt.ru,mitchenkosv@tver.atomsbt.ru,halinda@kursk.atomsbt.ru,hintbatg@atomsbt.ru,petrovain@kursk.atomsbt.ru,loktionovaos@kursk.atomsbt.ru,malykhinaaa@kursk.atomsbt.ru,rebaneaa@tver.atomsbt.ru,medvedevale@smolensk.atomsbt.ru,alekseevain@smolensk.atomsbt.ru,baryshnikovaiv@tver.atomsbt.ru,penkovamv@tver.atomsbt.ru,teleginmy@kursk.atomsbt.ru,parhomenkmv@smolensk.atomsbt.ru,molchanovms@kursk.atomsbt.ru,kamenevdg@kursk.atomsbt.ru,kondratevaav@murmansk.atomsbt.ru,alexeevain@smolensk.atomsbt.ru,4ekmareva77@mail.ru,korobeynikovaoa@tver.atomsbt.ru,voroninev@kursk.atomsbt.ru,arcybashevaa@kursk.atomsbt.ru,shubinami@tver.atomsbt.ru,dementevanv@kursk.atomsbt.ru,stepanovaim@smolensk.atomsbt.ru,davydenkovaes@smolensk.atomsbt.ru,volobuevdn@kursk.atomsbt.ru,matrosovda@tver.atomsbt.ru,suharevna@tver.atomsbt.ru,chuvashovdv@tver.atomsbt.ru,remezkp@smolensk.atomsbt.ru,kukovenkovalm@smolensk.atomsbt.ru,timashukse@atomsbt.ru,ovchinnikovang@kursk.atomsbt.ru,uzhekinmv@smolensk.atomsbt.ru,smerdinaka@tver.atomsbt.ru,zhukovro@tver.atomsbt.ru | V15: 3720000000 | W15: 91525482000 | X15: 3440924000 | Y15: 41834000 | Z15: 7311650000 | AA15: 9600061000 | AB15: 2769557000 | AC15: 3651692000 | AD15: 3654059000 | AG15: ОСН
A16: 1057746557329 | B16: 7736520080 | C16: АО "МОСЭНЕРГОСБЫТ" | D16: АКЦИОНЕРНОЕ ОБЩЕСТВО "МОСЭНЕРГОСБЫТ" | E16: 76469930 | F16: 45293554000 | G16: 16 | H16: 12267 | I16: 773601001 | J16: 2005-04-01 | L16: 35.14 | M16: Торговля электроэнергией | N16: 26.51,33.13,35.13,35.30.3,36.00.2,37.00,46.18.2,47.11,52.10.21,56.29,64.19,66.22,70.22,73.20.1,81.21,81.22,81.29,81.29.1,82.99,84.24,85.23,86.21,95.11,95.12,95.22 | O16: КОВАЛЕВ АНДРЕЙ ВИКТОРОВИЧ | P16: 344402643468 | Q16: ГЕНЕРАЛЬНЫЙ ДИРЕКТОР | R16: 117312, Г.МОСКВА, УЛ. ВАВИЛОВА, Д.9 | S16: +74962241666,+74959819819,+74991329933,+74957106022,+74986959533,+74964523852,+74955125694,+74995500333,+74967556287,+74999819819,+74995509716,+74995500318,+74995500319,+74991328401,+74965193854,+74995509721,+74964618942,+74967699922,+74965513211,+74957185822,+74965192800,+74991328544,+74995504110,+74952211867,+74995500494,+74965393200,+74995509819,+74995509550,+74995500303,+74995504135,+74955500333,+74955508929,+74959571359,+74955508324,+74955615429,+74955815429,+74953271396,+74951328640,+74952874491,+74953060707,+74953270035,+74956618403,+74951328440,+74952874490,+74951327956,+74953271904,+74952591779,+74959573814,+74952598160,+74951328400 | T16: nimanovbi@mosenergosbyt.ru,,www.e-disclosure.ru/portal/company.aspx?id=6980,,www.mosenergosbyt.ru | U16: dmitrovto@yandex.ru,parshinz_vv@mosenergosbyt.ru,info@mosenergosbyt.ru,lopatina_mg@interrao.ru,svo@mosenergosbyt.ru,kuzmicheva_es@mosenergosbyt.ru,nimanovbi@mosenergosbyt.ru,belova_ek@interrao.ru,cto@mosenergosbyt.ru,zhigovskaya_eg@mosenergosbyt.ru,viklenko@mosenergosbyt.ru,forosna@mosenergosbyt.ru,kuzmicheva@mosenergosbyt.ru,forostyan_na@mosenergosbyt.ru,00@jj.ru,okr-ogrdolg@mosenergosbyt.ru,info@mocenergosbyt.ru,chaykina_ev@mosenergosbyt.ru,sukhova_ose@mosenergosbyt.ru,null@null.ru,,sedova_sv@mosenergosbyt.ru,litvinova_aaa@mosenergosbyt.ru,g.lekovada@mosenergosbyt.ru,alekseeva_my@mosenergosbyt.ru,szo@mosenergosbyt.ru,chizhikovaeyu@mosenergosbyt.ru,kurmaevadf@mosenergosbyt.ru,mosenergo@mail.ru,titovaela@mosenergosbyt.ru,polyanskaya_en@mosenergosbyt.ru,skitaevatv@mosenergosbyt.ru,uspenskayaov@mosenergosbyt.ru,mejinen@mosenergosbyt.ru,fsvch6898@mail.ru,moesk@msk.ru,churushkin_av@mosenergosbyt.ru,chernyavskaya_ee@mosenergosbyt.ru,info@mosenergo.ru,andr.a.gorbunov@mail.ru,info@dantamedic.ru,pushkino@mosenеrgosbyt.ru,buh_uii@mail.ru,tender@puppet.ru,mosenergosbyt@mail.ru,zubkova_mv@mosenergosbyt.ru,emelyanova_nv@mosenergosbyt.ru,ingo@mosenergosbyt.ru,foreostyan_na@mosenergosbyt.ru,2061331@mail.ru,dfghsdrf@mail.ru | V16: 383004818 | W16: 629184846000 | X16: 25768124000 | Y16: 854380000 | Z16: 41285827000 | AA16: 79481382000 | AB16: 13839669000 | AC16: 21836396000 | AD16: 20883685000 | AG16: ОСН
A17: 1123444007070 | B17: 3444197347 | C17: ООО "ЛИКАРД" | D17: ОБЩЕСТВО С ОГРАНИЧЕННОЙ ОТВЕТСТВЕННОСТЬЮ "ЛУКОЙЛ-ИНТЕР-КАРД" | E17: 50513259 | F17: 45286560000 | G17: 16 | H17: 12300 | I17: 770501001 | J17: 2012-10-01 | L17: 46.71 | M17: Торговля оптовая твердым, жидким и газообразным топливом и подобными продуктами | N17: 22.29.2,33.12,46.12.1,46.90,47.19,47.21,47.22,47.23,47.24,47.25,47.26,47.29,47.30,47.78,47.99.2,56.10,62.09,63.11,63.11.1,66.11.2,66.19,66.19.6,68.10.22,70.22,73.11,73.20.1 | O17: ФИЛИППОВ АЛЕКСЕЙ ВИКТОРОВИЧ | P17: 774306802813 | Q17: ГЕНЕРАЛЬНЫЙ ДИРЕКТОР | R17: 115035, Г.МОСКВА, ВН.ТЕР.Г. МУНИЦИПАЛЬНЫЙ ОКРУГ ЗАМОСКВОРЕЧЬЕ, УЛ БОЛЬШАЯ ОРДЫНКА, Д. 3 | S17: +78442235767,+73422336156,+78442785261,+78212302614,+78442963373,+73422336147,+78312789821,+78442558003,+78172726010,+78844255800,+78001000911,+78442558005,+78842558003,+78612388932,+74966731232,+78312789877,+79226061077,+78124591989,+78315021746,+78221000911,+78124951987,+78124591897,+78124591987,+73422336145,+78612388938,+78312789801,+74955870770,+78172734180,+78312789803,+78132789821,+74959817033,+74957775977,+78182302619,+78442550803,+78172720610,+78312789819,+74955870711,+78314265245,+74959271677,+78312782512,+78612350515,+78212232526,+78800100091,+78442963376,+78314350101,+79994554550,+78612533418,+73422236145,+78612388936,+78172786010 | T17: www.licard.ru | U17: kmaksimova@licard.com,likard@mail.r,eis@licard.com,lk@mail.ru,ssychev@likard.com,contract@licard.com,ivasenina@licard.com,ekashintseva@licard.com,info@licard.ru,ytn@rambler.ru,erusova@likard.com,abochkareva@licard.com,rfotina@licard.com,iplakunova@licard.com,mborisova@licard.com,erusova@licard.ru,likar@yandex.ru,mtimoshinina@licard.com,mbeshanova@licard.com,erusova@licard.com,ssychev@licard.com,ndudko@licard.com,equest@licard.com,arezvanova@licard.com,robot@licard.ru,afomin@licard.com,info@licord.ru,ltimofeeva@licard.com,ecashintseva@likard.ru,spbsales@licard.com,ndevaeva@licard.com,pbsales@licard.com,contrakt@licard.com,myasyuk@licard.com,kanclend@mail.ru,ltimofeeva@likard.com,request@licard.com,0@0.ru,lantonova@licard.com,abochkateva@licard.com,areznikov@licard.com,info@likard.com,eefremova@licard.ru,no@mail.ru,timofeeva@likard.ru,svsmirnova@licard.com,ikard@mail.ru,licard@licard.com,abochkareva@likard.ru,ashevchenko@licard.com | V17: 697000000 | W17: 856318766000 | X17: 4669695000 | Y17: 23974288000 | Z17: 67553200000 | AA17: 80674971000 | AB17: 10505699000 | AC17: 14367566000 | AD17: 13964255000 | AG17: ОСН
A18: 1027700000679 | B18: 7701285928 | C18: ООО "ЛУКОЙЛ-ЦЕНТРНЕФТЕПРОДУКТ" | D18: ОБЩЕСТВО С ОГРАНИЧЕННОЙ ОТВЕТСТВЕННОСТЬЮ "ЛУКОЙЛ-ЦЕНТРНЕФТЕПРОДУКТ" | E18: 58388374 | F18: 45286570000 | G18: 16 | H18: 12300 | I18: 770201001 | J18: 2002-01-28 | L18: 47.30 | M18: Торговля розничная моторным топливом в специализированных магазинах | N18: 56.10.1,41.20,45.1,45.20,46.12,46.71,46.90,47.11,47.25,47.30,47.73,47.74,47.75,47.8,52.10.21,66.19,68.20.21,68.20.29,70.22,71.11,71.12.2,71.20,85.30 | O18: НЕСТЕРЕНКО АЛЕКСАНДР НИКОЛАЕВИЧ | P18: 27411637338 | Q18: ГЕНЕРАЛЬНЫЙ ДИРЕКТОР | R18: 129110, Г.МОСКВА, ВН.ТЕР.Г. МУНИЦИПАЛЬНЫЙ ОКРУГ МЕЩАНСКИЙ, ПР-КТ ОЛИМПИЙСКИЙ, Д. 5, СТР. 1 | S18: +79191478316,+74959817450,+74957717232,+74956278888,+74959817472,+74956232902,+79163287387,+74956278229,+74959817679,+79168094424,+79067893050,+79266287671,+79261468949,+74832744840,+74862434551,+74832666360,+74742222524,+74956278018,+74956272823,+74959803131,+74956278223,+74956271278,+74959817481,+74959817672,+78002002425,+70959339450,+74812322567,+74812322368,+74872347078,+74872345593,+74742223803,+74742223804,+78314623074,+70959817672,+74957806022,+74959817596,+74955040529,+70009817596,+74959817594,+74956278277,+74959339450 | T18: www.luknef.lukoil.ru | U18: luknef@lukoil.com,ekaterina.desyatkova@lukoil.com,alexander.chubenko@lukoil.com,luknef@luknef.ru,hotline@luknef.ru,,marina.ruchko@lukoil.com,kolosova@lukoil.com,nadejda.plyonkina@lukoil.com | V18: 2379785955 | W18: 267315840000 | X18: 32283127000 | Y18: 4055671000 | Z18: 5727253000 | AA18: 15703400000 | AB18: 17636607000 | AC18: 24890074000 | AD18: 23450204000 | AG18: ОСН
A19: 1107746744038 | B19: 7743792870 | C19: ООО "ТЕБОЙЛ РУС" | D19: ОБЩЕСТВО С ОГРАНИЧЕННОЙ ОТВЕТСТВЕННОСТЬЮ "ТЕБОЙЛ РУС" | E19: 17216218 | F19: 45286585000 | G19: 16 | H19: 12300 | I19: 771001001 | J19: 2010-09-13 | L19: 47.30 | M19: Торговля розничная моторным топливом в специализированных магазинах | N19: 19.20,43.99,46.71,47.11,52.10.21,56.10.2,56.10.21,62.09,63.11,68.10,68.20,71.12,77.39 | O19: МАСЛОВ ВИТАЛИЙ ГЕННАДИЕВИЧ | P19: 773423718948 | Q19: ГЕНЕРАЛЬНЫЙ ДИРЕКТОР | R19: 125196, Г.МОСКВА, УЛ. ЛЕСНАЯ, Д. 9, ЭТАЖ 3 | S19: +74952585900,+74952586920,+74825193005,+74999232101,+74952586900,+74952586924,+78123801212,+74825193000,+78123801011,+78137825418,+78137825417 | T19: www.shell.com.ru | U19: zakaz-b2c-ru@shell.com,maria.suslenkova@shell.com,techinfo@shell.com,s.botev@shell.com | V19: 2964177663 | W19: 110040896000 | X19: 30805627000 | Y19: 4359064000 | Z19: 7983458000 | AA19: 10698386000 | AB19: 1599414000 | AC19: 2941281000 | AD19: 2161469000 | AG19: ОСН
A20: 1047796118182 | B20: 7706525041 | C20: ООО "РН-ЭНЕРГО" | D20: ОБЩЕСТВО С ОГРАНИЧЕННОЙ ОТВЕТСТВЕННОСТЬЮ "РН-ЭНЕРГО" | E20: 72147789 | F20: 46439566000 | G20: 16 | H20: 12300 | I20: 502401001 | J20: 2004-02-26 | L20: 35.14 | M20: Торговля электроэнергией | N20: 33.13,33.14,33.20,35.11,35.14,43.21,43.29,45.20.5 | O20: КУЛЫГИН НИКОЛАЙ ВЛАДИМИРОВИЧ | P20: 590405256690 | Q20: ГЕНЕРАЛЬНЫЙ ДИРЕКТОР | R20: 143440, МОСКОВСКАЯ ОБЛАСТЬ, Г.О. КРАСНОГОРСК, ПГТ. ПУТИЛКОВО, ТЕР. ГРИНВУД, СТР. 23, ЭТАЖ 2, ПОМЕЩ. 129 | S20: +74952313182,+74957774724,+74954284096,+74995766596,+74957774477,+74992313182,+74957774742,+78126111905,+79181200809,+73463332217,+79657546297,+74955766596,+73493654743,+73463313445,+73493653214,+79277362627,+73955403752,+78655822169,+73955572940,+73412606865,+73463253548,+74957777742,+74953214568,+78861464426,+73825966034,+78412550820,+73463253549,+73463253508,+78466120447,+74995766595,+78466141209,+73825963395,+74956648840 | T20: www.rosneft.ru/about | U20: e_mochalova@rosneft.ru,rn-energo.ru@rn-energo.ru,kann@pesc.ru,v_sokirka@mail.ru,rn-energo@rn-enerao.ru,m-energo@m-energo.ru,zsg@pesc.ru,energ@mail.ru,rn-energo@energo.ru,rn-energo@rn_energo.ru,rn-energo@rn-energo.eu,rn-energo@rn-energo.ru,kochneva@belkam.com,fff@ffff.ff,gatinim@yungjsc.com,s_chistyakova@rn-energo.ru,chistyakova_no-reply@rn-energo.ru,rn@rn.ru,e_mochalova@rosneft.ru,,info@rnenergo.ru,d_savchuk86@mail.ru,d.rumyantseva@in-tex.ru,pr@rosneft.ru,alyautdinova@mroads.ru,gatinim@energy.yugjsc.com,-@mail.ru,antoshukli@energoneft-t.ru,rn-energo@rn-energo.com,1@1.ru,svfdogovor@bk.ru,raysihea@energy.yungjsc.com,tek@energosales.ru,n_kannabikh@rn-energo.ru,zatulivetrov_mv@interrao.ru,o_titaeva@rn-enegro.ru,o_titaeva@rn-energo.ru,o_titaeva@rn-enrgo.ru | V20: 5010000 | W20: 155711309000 | X20: 279773000 | Y20: 177000 | Z20: 9509601000 | AA20: 16070179000 | AB20: 10457635000 | AC20: 5836302000 | AD20: 14031060000 | AG20: ОСН
A21: 1117746105400 | B21: 7707743204 | C21: АО "ФОРТЕИНВЕСТ" | D21: АКЦИОНЕРНОЕ ОБЩЕСТВО "ФОРТЕИНВЕСТ" | E21: 90531706 | F21: 45286585000 | G21: 34 | H21: 12267 | I21: 770701001 | J21: 2011-02-16 | L21: 46.71.2 | M21: Торговля оптовая моторным топливом, включая авиационный бензин | N21: 06.10,06.10.1,06.20,19.20,46.12.1,52.29,64.99,66.19.4,70.22,84.11.4 | O21: КОЗЛОВ ВИТАЛИЙ ВЛАДИМИРОВИЧ | P21: 623002845248 | Q21: ГЕНЕРАЛЬНЫЙ ДИРЕКТОР | R21: 127055, Г.МОСКВА, УЛ. НОВОСЛОБОДСКАЯ, Д. 41, ЭТАЖ 6 ПОМЕЩЕНИЕ I | S21: +74956415900,+79857667887,+71417487170,+71417487171,+74956415908,+74956415909 | T21: forteinvest.ru | U21: info@forteinvest.ru,info@forteinvest.ru,,sokolovasa@forteinvest.ru,,kuleshovsi@forteinvest.ru | V21: 20000000 | W21: 297264349000 | X21: 393142000 | Y21: 6866107000 | Z21: 46405227000 | AA21: 28374720000 | AB21: 9346312000 | AC21: 23413924000 | AD21: 12217038000 | AG21: ОСН
A22: 1087746480348 | B22: 7704685184 | C22: АО "НК "НЕФТИСА" | D22: АКЦИОНЕРНОЕ ОБЩЕСТВО "НЕФТЯНАЯ КОМПАНИЯ "НЕФТИСА" | E22: 85741809 | F22: 45286585000 | G22: 16 | H22: 12267 | I22: 771001001 | J22: 2008-04-07 | L22: 46.71.3 | M22: Торговля оптовая нефтью | N22: 06.10.1,06.10.3,08.12.1,09.1,09.10.9,19.20,46.12.1,46.71.2,47.30,52.10.21,52.10.22,52.29,62.02,62.02.1,62.02.2,62.02.3,62.02.4,62.02.9,62.03,62.03.1,62.03.11,62.03.12,62.03.13,62.03.19,62.09,63.11,63.11.1,63.11.9,63.12,66.12.2,69.20.2,70.22,71.12.3,72.19,73.11,73.20.1,74.90.3,74.90.9,74.90.92,74.90.93,74.90.94,74.90.99,82.99 | O22: Зарубин Андрей Леонидович | P22: 860301402225 | Q22: ГЕНЕРАЛЬНЫЙ ДИРЕКТОР | R22: 125375, Г.МОСКВА, ВН.ТЕР.Г. МУНИЦИПАЛЬНЫЙ ОКРУГ ТВЕРСКОЙ, УЛ ТВЕРСКАЯ, Д. 22/2, К. 1, ЭТАЖ 5, КОМ. 5-34 | S22: +74956275585 | T22: www.e-disclosure.ru/portal/company.aspx?id=14687,neftisa.ru | V22: 55000000 | W22: 89133427000 | X22: 976182000 | Y22: 193000 | Z22: 54767601000 | AA22: 109184387000 | AB22: -4678875000 | AC22: 3355955000 | AD22: -5727520000 | AG22: ОСН
A23: 1157746958830 | B23: 7724338125 | C23: ООО "НОВЫЙ АЙ ТИ ПРОЕКТ" | D23: ОБЩЕСТВО С ОГРАНИЧЕННОЙ ОТВЕТСТВЕННОСТЬЮ "НОВЫЙ АЙ ТИ ПРОЕКТ" | E23: 51207582 | F23: 45296571000 | G23: 16 | H23: 12300 | I23: 772401001 | J23: 2015-10-20 | L23: 46.51 | M23: Торговля оптовая компьютерами, периферийными устройствами к компьютерам и программным обеспечением | N23: 26.20.1,26.20.2,26.20.3,26.20.4,26.20.9,43.21,43.22,43.29,46.15.3,46.15.4,46.19,46.43.1,46.43.2,46.43.3,46.49.42,46.66,46.69.7,46.90,47.91.1,47.91.2,52.10,52.10.9,52.21.2,52.24,52.24.1,52.24.2,52.29,61.10,61.10.1,61.10.4,61.10.9,61.20,61.30,61.90,62.01,62.02,62.03,62.09,63.11,63.11.1,63.12,63.91,63.99,63.99.1,73.11,73.12,73.20,73.20.1,79.90,95.11,95.12,95.21 | O23: ТКАЧЕВ СТАНИСЛАВ ИГОРЕВИЧ | P23: 232307152273 | Q23: ГЕНЕРАЛЬНЫЙ ДИРЕКТОР | R23: 115487, Г.МОСКВА, УЛ. НАГАТИНСКАЯ, Д. 16, СТР. 9, ПОМЕЩ. VII КОМ.15 ОФ.5 | S23: +74952077586,+74952077557,+74959266632,+74959269136,+79031090589,+79252412639,+79197276307,+74742220555 | U23: tender@3l.ru,e.karabanova28@gmail.com,info@3l.ru,e.karabanova28@gmai.ru,kazartsev@3l.ru,tender@regard.lipetsk.ru,info@3l.mail.ru,e.karabanova28@gmail.ru,vsevolod@3l.ru,hgjfnnnhh@mail.ru,mshapovalov@31.ru | V23: 100000000 | W23: 102474602000 | X23: 4378373000 | Y23: 27018478000 | Z23: 31901047000 | AA23: 24670520000 | AB23: 2048524000 | AC23: 7417390000 | AD23: 2814624000 | AG23: ОСН
A24: 1147746128694 | B24: 7725819008 | C24: ООО "МЕДСКАН" | D24: ОБЩЕСТВО С ОГРАНИЧЕННОЙ ОТВЕТСТВЕННОСТЬЮ "МЕДСКАН" | E24: 28946948 | F24: 45293578000 | G24: 16 | H24: 12300 | I24: 772801001 | J24: 2014-02-14 | L24: 86.10 | M24: Деятельность больничных организаций | N24: 33.13,46.18.1,46.46,47.73,47.74,47.75,73.11,77.39.26 | O24: ПОДТЕТЕНЕВ ДМИТРИЙ СЕРГЕЕВИЧ | P24: 770470783064 | Q24: ГЕНЕРАЛЬНЫЙ ДИРЕКТОР | R24: 119421, Г.МОСКВА, УЛ. ОБРУЧЕВА, Д. 21А | S24: +74951220303,+74951261620,+74956688181,+79031060530,+79161409478 | V24: 2198902242 | W24: 707049000 | X24: 516551000 | Y24: 25207000 | Z24: 42561000 | AA24: 158705000 | AB24: -109939000 | AC24: -43974000 | AD24: -132610000 | AF24: 98 | AG24: ОСН
A25: 1117746708078 | B25: 7705961278 | C25: АО "ВО "ТЯЖПРОМЭКСПОРТ" | D25: АКЦИОНЕРНОЕ ОБЩЕСТВО "ВНЕШНЕЭКОНОМИЧЕСКОЕ ОБЪЕДИНЕНИЕ "ТЯЖПРОМЭКСПОРТ" | E25: 2839020 | F25: 45277598000 | G25: 12 | H25: 12267 | I25: 771401001 | J25: 2011-09-08 | L25: 41.20 | M25: Строительство жилых и нежилых зданий | N25: 41.2,46.14,46.90,68.2,71.1,71.12.5,71.12.6,73.11,73.20.1,78.1,82.99 | O25: ЕГОРОВ СЕРГЕЙ АНАТОЛЬЕВИЧ | P25: 773128953616 | Q25: ГЕНЕРАЛЬНЫЙ ДИРЕКТОР | R25: 125284, Г.МОСКВА, ПР-Д 1-Й ХОРОШЁВСКИЙ, Д. 3А, СТР. 2 | S25: +74996480000,+74959415100,+74959412552,+74959412060,+74959412694,+74959412072,+74959416020,+74959410433,+74959415101,+74959413617,+74959413716,+79104635472,+74959412090,+74959412555,+74959413955,+74959501610,+79035097146,+74959415022,+79459412072,+79039412694 | T25: tyazh.ru | U25: i.kostina@tyazh.ru,e.duyunova@tyazh.ru,info@tyazh.ru,eduynova@tyazh.ru,e.duynova@mail.ru,e.dyunova@tyazh.ru,v.melnikova@tyazh.ru,a.mikhailov@tyazh.ru,,tyazh@dol.ru,,g.volkenshtein@tyazh.ru,,e.duynova@tyazh.ru,i.stenichkov.@tyazh.ru,i.stenichkov@tyazh.ru,g.volkenshtein@tyazh.ru,a.mikhailov@tyazh.ru,d.dzhambulat@tyazh.ru,a/mikhailov@tyazh.ru | V25: 1739643000 | W25: 1720796000 | X25: 66038000 | Y25: 64711000 | Z25: 1481485000 | AA25: 3190715000 | AB25: 1927000 | AC25: -9441000 | AD25: 12225000 | AF25: 62 | AG25: ОСН
A26: 1037739941227 | B26: 7705568878 | C26: АО "СОГАЗ ТАУЭР" | D26: АКЦИОНЕРНОЕ ОБЩЕСТВО "СОГАЗ ТАУЭР" | E26: 71593328 | F26: 45286565000 | G26: 16 | H26: 12267 | I26: 770801001 | J26: 2003-11-03 | L26: 68.20.29 | M26: Аренда и управление собственным или арендованным прочим нежилым недвижимым имуществом | N26: 41.20,64.99.3,68.10,68.20,68.31,68.32,68.32.2,70.22,71.11,73.11,73.20.1 | O26: НЕЧАЕВ ГЕОРГИЙ ВИКТОРОВИЧ | P26: 772700728603 | Q26: ГЕНЕРАЛЬНЫЙ ДИРЕКТОР | R26: 107078, Г.МОСКВА, ПР-КТ АКАДЕМИКА САХАРОВА, Д. 10 | S26: +74956606015,+74956431315,+74956431316 | U26: wave@wavetower.ru | V26: 5446257100 | W26: 261246000 | X26: 23684000 | Y26: 0 | Z26: 585380000 | AA26: 6547028000 | AB26: 3935822000 | AC26: -5151000 | AD26: 3981045000 | AF26: 0 | AG26: ОСН
A27: 1035001602570 | B27: 5007032441 | C27: АО "АГРОФИРМА "ОРУДЬЕВСКОЕ" | D27: АКЦИОНЕРНОЕ ОБЩЕСТВО "АГРОФИРМА "ОРУДЬЕВСКОЕ" | E27: 3509402 | F27: 46415000499 | G27: 16 | H27: 12267 | I27: 500701001 | J27: 2002-06-21 | L27: 68.1 | M27: Покупка и продажа собственного недвижимого имущества | N27: 01.42,52.24.2,52.29,64.92,68.2 | O27: КОМАРОВ ОЛЕГ ВАЛЕНТИНОВИЧ | P27: 772580524669 | Q27: ГЕНЕРАЛЬНЫЙ ДИРЕКТОР | R27: 141825, МОСКОВСКАЯ ОБЛАСТЬ, М.О. ДМИТРОВСКИЙ, С ОРУДЬЕВО, УЛ ЦЕНТРАЛЬНАЯ, Д. 87А, ПОМЕЩ. 28 | S27: +74959939868,+74969939868 | V27: 1649943000 | W27: 264331000 | X27: 0 | Y27: 567858000 | Z27: 1274240000 | AA27: 6061000 | AB27: -431443000 | AC27: -205576000 | AD27: -431443000 | AE27: Микропредприятие | AF27: 3 | AG27: УСН
A28: 1035001610808 | B28: 5007041559 | C28: ООО "МДК" | D28: ОБЩЕСТВО С ОГРАНИЧЕННОЙ ОТВЕТСТВЕННОСТЬЮ "МДК" | E28: 13369267 | F28: 46415000329 | G28: 16 | H28: 12300 | I28: 500701001 | J28: 2003-04-02 | L28: 55.10 | M28: Деятельность гостиниц и прочих мест для временного проживания | N28: 41.2,43.12,43.12.3,43.2,43.3,43.33,43.99.1,43.99.4,43.99.6,43.99.7,45.20.1,45.20.2,47.11.2,47.30,52.29,55.30,55.90,56.10,56.10.1,56.10.3,56.30,68.2,77.21,79.11,86.90.4,88.10,93.11,93.19,96.02,96.04 | O28: ЮДЕНКОВ НИКОЛАЙ ЕВГЕНЬЕВИЧ | P28: 771526598212 | Q28: ГЕНЕРАЛЬНЫЙ ДИРЕКТОР | R28: 141840, МОСКОВСКАЯ ОБЛАСТЬ, М.О. ДМИТРОВСКИЙ, Д КУРОВО, Д. 69 | S28: +74957967504,+74957888512,+74952680243 | T28: www.dmitrov.golf,sorochany-mdk.ru | U28: info@dmitrov.golf,corp@dmitrov.golf,secretaru@sorochany-mdk.ru,secretary@sorochany-mdk.ru | V28: 240000000 | W28: 160710000 | X28: 38291000 | Y28: 8661000 | Z28: 66395000 | AA28: 141278000 | AB28: -742000 | AC28: -27854000 | AD28: -127000 | AE28: Малое предприятие | AF28: 51 | AG28: ОСН
A29: 1037789058900 | B29: 7702511168 | C29: АО "ЭКСР" | D29: АКЦИОНЕРНОЕ ОБЩЕСТВО "ЭБЕРСПЕХЕР КЛИМАТИЧЕСКИЕ СИСТЕМЫ РУС" | E29: 72081725 | F29: 45286575000 | G29: 23 | H29: 12267 | I29: 770301001 | J29: 2003-12-17 | L29: 45.31.1 | M29: Торговля оптовая автомобильными деталями, узлами и принадлежностями, кроме деятельности агентов | N29: 28.25.1,28.25.12,28.25.13,28.25.2,29.31,29.32,29.32.3,45.20,45.31.1,45.31.2,45.32,52.10,52.24,52.29,74.20,74.30,82.19,82.92,82.99 | O29: ВОСТРОПЯТОВА МАРИНА ВЛАДИМИРОВНА | P29: 504704660886 | Q29: Генеральный директор | R29: 123104, Г.МОСКВА, ВН.ТЕР.Г. МУНИЦИПАЛЬНЫЙ ОКРУГ ПРЕСНЕНСКИЙ, Б-Р ТВЕРСКОЙ, Д. 13, СТР. 1 | S29: +74956471324,+78002003237,+74956455979,+74952120590,+70957558127,+70959248551,+74957558127 | T29: www.otem.ru | U29: info-ru@eberspacher.com,info-ru@eberspaecher.com | V29: 302870000 | W29: 505550000 | X29: 1319000 | Y29: 284787000 | Z29: 125703000 | AA29: 220027000 | AB29: 24012000 | AC29: -11445000 | AD29: 40861000 | AF29: 27 | AG29: ОСН
A30: 1037789057305 | B30: 7714528631 | C30: ООО "СЕВЕРНЫЙ АВТОВОКЗАЛ" | D30: ОБЩЕСТВО С ОГРАНИЧЕННОЙ ОТВЕТСТВЕННОСТЬЮ "СЕВЕРНЫЙ АВТОВОКЗАЛ" | E30: 71678361 | F30: 45277598000 | G30: 23 | H30: 12300 | I30: 771401001 | J30: 2003-12-17 | L30: 55.10 | M30: Деятельность гостиниц и прочих мест для временного проживания | N30: 41.20,43.11,43.12.3,43.91,43.99,43.99,55.10,56.10.1,68.10,68.10.1,68.20,68.32,70.22,71.1,71.11,71.12.5,71.12.6 | O30: БАЛТАОГЛУ ДЖЮНЕЙТ | P30: 770871662067 | Q30: ГЕНЕРАЛЬНЫЙ ДИРЕКТОР | R30: 125167, Г.МОСКВА, ПР-КТ ЛЕНИНГРАДСКИЙ, Д.37, К.8 | S30: +74996540320,+70954824592,+74954824592 | V30: 136709700 | W30: 257602000 | X30: 26703000 | Y30: 446000 | Z30: 84042000 | AA30: 19114000 | AB30: 82861000 | AC30: 167883000 | AD30: 111871000 | AF30: 4 | AG30: ОСН
A31: 1035005002361 | B31: 5027023420 | C31: ООО "ЛИДЕР" | D31: ОБЩЕСТВО С ОГРАНИЧЕННОЙ ОТВЕТСТВЕННОСТЬЮ "ЛИДЕР" | E31: 18192537 | F31: 46448561000 | G31: 16 | H31: 12300 | I31: 502701001 | J31: 1992-09-22 | L31: 49.4 | M31: Деятельность автомобильного грузового транспорта и услуги по перевозкам | N31: 10.32,11.07,11.07.2,29.20,29.20.5,45.20,45.20.1,46.16.2,46.17.1,52.10,68.20,68.20.1,70.10.2,77.11,77.12 | O31: МИРОШКИН АЛЕКСАНДР АЛЕКСЕЕВИЧ | P31: 500510664429 | Q31: ДИРЕКТОР | R31: 140032, МОСКОВСКАЯ ОБЛАСТЬ, Г ЛЮБЕРЦЫ, ПГТ. МАЛАХОВКА, УЛ ГАРАЖНАЯ, Д. 3 | S31: +74955012311,+74955013572,+74955019754,+74985013572,+74985012311,+79035964869,+74955011218 | U31: kazakova@liderco.ru | V31: 580621789 | W31: 285141000 | X31: 49009000 | Y31: 1338000 | Z31: 180751000 | AA31: 21063000 | AB31: 328715000 | AC31: 47337000 | AD31: 342196000 | AE31: Малое предприятие | AF31: 73 | AG31: ОСН
A32: 1035006452711 | B32: 5032014816 | C32: ООО ДСЭ " ОСЕНЬ " | D32: ОБЩЕСТВО С ОГРАНИЧЕННОЙ ОТВЕТСТВЕННОСТЬЮ ДИРЕКЦИЯ ПО СТРОИТЕЛЬСТВУ И ЭКСПЛУАТАЦИИ " ОСЕНЬ " | E32: 31322522 | F32: 46455000513 | G32: 23 | H32: 12300 | I32: 503201001 | J32: 1991-09-20 | L32: 68.32.1 | M32: Управление эксплуатацией жилого фонда за вознаграждение или на договорной основе | N32: 01.61,43.99,66.12,68.2,68.32.1,73.20.1,93.19 | O32: ЧЕПРАСОВА ЕЛЕНА ВИКТОРОВНА | P32: 771502261562 | Q32: ГЕНЕРАЛЬНЫЙ ДИРЕКТОР | R32: 143026, МОСКОВСКАЯ ОБЛАСТЬ, Г ОДИНЦОВО, УЛ ОСЕННЯЯ (НЕМЧИНОВО ТЕР.), Д. 1 | S32: +74952335476,+74954149675,+74957481006,+74957480088,+79166216584 | V32: 231250250 | W32: 121105000 | X32: 172255000 | Y32: 1684000 | Z32: 68216000 | AA32: 7322000 | AB32: 17000 | AC32: 100000 | AD32: 24000 | AF32: 38 | AG32: ОСН
A33: 1127746400759 | B33: 7726697521 | C33: ООО "НИЦЭВТ-ЭНЕРГО" | D33: ОБЩЕСТВО С ОГРАНИЧЕННОЙ ОТВЕТСТВЕННОСТЬЮ "НИЦЭВТ-ЭНЕРГО" | E33: 9814313 | F33: 45296593000 | G33: 16 | H33: 12300 | I33: 772601001 | J33: 2012-05-24 | L33: 35.11.1 | M33: Производство электроэнергии тепловыми электростанциями, в том числе деятельность по обеспечению работоспособности электростанций | N33: 33.12,33.12,33.12,33.12,33.12,33.12,33.14,33.14,33.14,33.20,35.11,35.11.4,35.30,35.30.1,35.30.11,35.30.13,35.30.14,35.30.15,35.30.2,35.30.3,35.30.4,35.30.5,36.00,36.00.1,36.00.2,41.20,41.20,42.21,42.21,42.22.2,42.22.3,42.99,43.11,43.11,43.12.1,43.12.3,43.21,43.22,43.29,43.31,43.32,43.33,43.34,43.34.1,43.34.2,43.39,43.91,43.99,43.99,43.99.1,43.99.2,43.99.3,43.99.4,43.99.5,43.99.6,43.99.7,43.99.9,46.12.1,46.71.2,47.52.73,47.78.6,49.50,49.50.2,49.50.21,52.10,52.10.2,52.10.22,52.10.23,52.21,52.21.2,68.10,68.10.1,68.10.12,68.20,68.20.2,68.31.1,68.31.12,68.31.2,68.31.22,68.31.3,68.31.32,68.31.4,68.31.42,68.31.5,68.32,68.32,68.32.2,70.22,71.11.1,71.12,71.12.1,71.12.12,71.12.13,71.12.45,71.20.6,71.20.9,73.20,73.20.1,73.20.2,77.39.23,81.22,81.29.9 | O33: СУКОВАТИКОВ РОМАН ПАВЛОВИЧ | P33: 503002547849 | Q33: ГЕНЕРАЛЬНЫЙ ДИРЕКТОР | R33: 117587, Г.МОСКВА, ВН.ТЕР.Г. МУНИЦИПАЛЬНЫЙ ОКРУГ ЧЕРТАНОВО СЕВЕРНОЕ, Ш ВАРШАВСКОЕ, Д. 125, СТР. 1, СЕКЦИЯ/ЭТАЖ/ПОМЕЩ. 3/5/IX, КОМ. 2 | S33: +79032582997,+79255068451,+74953196067 | T33: nicevt-energo.ru | V33: 393990122 | W33: 408872000 | X33: 679870000 | Y33: 0 | Z33: 114218000 | AA33: 126359000 | AB33: 61141000 | AC33: 132120000 | AD33: 81520000 | AF33: 12 | AG33: ОСН
A34: 1127746460434 | B34: 7733805552 | C34: ООО "МПС СОФТ" | D34: ОБЩЕСТВО С ОГРАНИЧЕННОЙ ОТВЕТСТВЕННОСТЬЮ "МАСТЕР ПРОДАКШН СОФТ ЭНД СИСТЕМЗ" | E34: 9875243 | F34: 45286555000 | G34: 16 | H34: 12300 | I34: 770101001 | J34: 2012-06-13 | L34: 62.0 | M34: Разработка компьютерного программного обеспечения, консультационные услуги в данной области и другие сопутствующие услуги | N34: 18.2,18.20,26.51,26.51.7,33.20,43.2,43.21,46.43.3,46.51,46.69.5,62.02,62.09,63.11.1,71.1,71.12.5,71.12.6,95.1 | O34: ОЛЬХОВ ВЛАДИМИР ПЕТРОВИЧ | P34: 644922752422 | Q34: ГЕНЕРАЛЬНЫЙ ДИРЕКТОР | R34: 105066, Г.МОСКВА, ВН.ТЕР.Г. МУНИЦИПАЛЬНЫЙ ОКРУГ БАСМАННЫЙ, УЛ НИЖНЯЯ КРАСНОСЕЛЬСКАЯ, Д. 40/12, К. 2, ПОМЕЩ. 1Н/3 | S34: +79266295688 | T34: rs485.ru | V34: 203381000 | W34: 662903000 | X34: 8123000 | Y34: 5918000 | Z34: 124493000 | AA34: 27779000 | AB34: 258905000 | AC34: 237791000 | AD34: 258905000 | AE34: Малое предприятие | AF34: 129 | AG34: ОСН
A35: 1125001005997 | B35: 5001091698 | C35: ООО "ТАРУСОВО-ДЕВЕЛОПМЕНТ" | D35: ОБЩЕСТВО С ОГРАНИЧЕННОЙ ОТВЕТСТВЕННОСТЬЮ "ТАРУСОВО-ДЕВЕЛОПМЕНТ" | E35: 18186531 | F35: 46478000771 | G35: 16 | H35: 12300 | I35: 507801001 | J35: 2012-12-13 | L35: 55.10 | M35: Деятельность гостиниц и прочих мест для временного проживания | N35: 56.10.1,64.99.11,64.99.3,68.1,68.2,68.3,68.31.1,68.31.2,68.31.3,68.31.4,77.32 | O35: ПОНОМАРЕНКО ЮЛИЯ АНАТОЛЬЕВНА | P35: 251101083838 | Q35: ГЕНЕРАЛЬНЫЙ ДИРЕКТОР | R35: 141932, МОСКОВСКАЯ ОБЛАСТЬ, Г.О. ТАЛДОМСКИЙ, Д ТАРУСОВО, ТЕР. ЛЕПОТА, Д. 1, ЭТАЖ 1, ПОМЕЩ. 15 | S35: +79057133446,+74952044091,+79858128507,+79653050174,+74956600644 | U35: notary@notarys.ru | V35: 168720737 | W35: 107202000 | X35: 146912000 | Y35: 399000 | Z35: 13414000 | AA35: 311675000 | AB35: 312000 | AC35: 19057000 | AD35: 577000 | AE35: Микропредприятие | AF35: 0 | AG35: ОСН
A36: 1167746525726 | B36: 7714391183 | C36: ООО "МЕДИА ЭКСТЕНШНС" | D36: ОБЩЕСТВО С ОГРАНИЧЕННОЙ ОТВЕТСТВЕННОСТЬЮ "МЕДИА ЭКСТЕНШНС" | E36: 2837541 | F36: 45277598000 | G36: 16 | H36: 12300 | I36: 771401001 | J36: 2016-06-02 | L36: 68.20 | M36: Аренда и управление собственным или арендованным недвижимым имуществом | N36: 18.12,43.21,58.11,58.14,59.11,60.10,60.20,61.10,62.01,62.02,62.09,63.11.1,64.99,68.31.1,68.31.2,68.31.3,68.31.4,68.32,70.22,71.11.1,72.20,73.11,74.30,77.11,77.33,78.30,80.10,80.20,80.30,81.22,81.29.9,82.19,82.99,90.0,91.01,93.11,93.29,95.11 | O36: ЛОБАШОВ ИЛЬЯ АНДРЕЕВИЧ | P36: 772826566206 | Q36: ГЕНЕРАЛЬНЫЙ ДИРЕКТОР | R36: 125284, Г.МОСКВА, Ш. ХОРОШЁВСКОЕ, Д. 32А, ПОМЕЩ. VII КОМН 46 | S36: +74959402025 | V36: 100100000 | W36: 144543000 | X36: 141907000 | Y36: 2000 | Z36: 4927000 | AA36: 9593000 | AB36: 79375000 | AC36: 0 | AD36: 0 | AE36: Микропредприятие | AF36: 2 | AG36: ОСН
A37: 1127747086367 | B37: 7708773522 | C37: ООО "ДЕЛЬТАХОЛДИНГ" | D37: ОБЩЕСТВО С ОГРАНИЧЕННОЙ ОТВЕТСТВЕННОСТЬЮ "ДЕЛЬТАХОЛДИНГ" | E37: 13238714 | F37: 45296559000 | G37: 16 | H37: 12300 | I37: 772501001 | J37: 2012-10-26 | L37: 77.39.12 | M37: Аренда и лизинг железнодорожного транспорта и оборудования | N37: 30.2,30.20.4,30.20.9,33.17,46.69.1,46.72,49.10,49.20,52.21.1,70.22 | O37: СОЛОВЬЁВА ИРИНА АЛЕКСАНДРОВНА | P37: 772584155116 | Q37: ГЕНЕРАЛЬНЫЙ ДИРЕКТОР | R37: 115114, Г.МОСКВА, ВН.ТЕР.Г. МУНИЦИПАЛЬНЫЙ ОКРУГ ДАНИЛОВСКИЙ, ПЕР 1-Й КОЖЕВНИЧЕСКИЙ, Д. 6, СТР. 1, ПОМЕЩ. 8/4 | S37: +79852273175 | U37: info@delta-holding.ru,aleksandrakareva@mail.ru | V37: 200000000 | W37: 194446000 | X37: 618032000 | Y37: 16000 | Z37: 133531000 | AA37: 14871000 | AB37: -26682000 | AC37: 33022000 | AD37: -35486000 | AE37: Микропредприятие | AF37: 1 | AG37: ОСН
A38: 1135042007539 | B38: 5042129460 | C38: ООО "ПСБ БИЗНЕС" | D38: ОБЩЕСТВО С ОГРАНИЧЕННОЙ ОТВЕТСТВЕННОСТЬЮ "ПСБ БИЗНЕС" | E38: 18098784 | F38: 45286590000 | G38: 16 | H38: 12300 | I38: 770401001 | J38: 2013-09-23 | L38: 55.10 | M38: Деятельность гостиниц и прочих мест для временного проживания | N38: 41.20,43.21,43.22,43.29,43.31,43.32,43.33,43.91,43.99,52.10,68.10,68.10.1,68.10.11,68.10.12,68.20,68.31,68.31.1,68.31.2,68.31.3,68.31.4,68.31.5,68.32,68.32.1,68.32.2,69.10,69.20,71.11,71.12,71.12.2,74.10,82.30,93.11,93.19 | O38: Доступ к сведениям ограничен | P38: — | Q38: — | R38: 119021, Г.МОСКВА, ВН.ТЕР.Г. МУНИЦИПАЛЬНЫЙ ОКРУГ ХАМОВНИКИ, УЛ ЛЬВА ТОЛСТОГО, Д. 23, СТР. 3, ПОМЕЩ. II, КОМ. 1К, 1Л, 1М, 1Н, 1О, 1П | S38: +74957771020,+79032754278 | U38: dzo.procurement@psbank.ru,korotkovatv@psbank.ru,piladzisoa@psbank.ru | V38: 1716624000 | W38: 656240000 | X38: 24556000 | Y38: 22592000 | Z38: 1209608000 | AA38: 2005416000 | AB38: -1662061000 | AC38: -422492000 | AD38: -1623384000 | AF38: 74 | AG38: ОСН
